Workbook

Sheet SurveyRpt_20150223 (1)
A1: NOTE: All summary and statistic calculations in this report are based on total number of responses to this survey.
A2: Individual question responses are not considered in these calculations.
A4: Survey: | B4: MQ Survey Q1 2015 | J4: Responses
A5: Section 1: | J5: Possible | K5: Total | L5: Average
A6: Question 1: | B6: 1. I agree with the benchmarks set for me on my team’s performance board? | J6: 1 | K6: 566 | L6: 0.8
A7: Question 2: | B7: 2. The standard claim processes / job aids clarify what is expected of me? | J7: 1 | K7: 553 | L7: 0.8
A8: Question 3: | B8: 3. The team structure and work processes support the standards expected of me? | J8: 1 | K8: 502 | L8: 0.7
A9: Question 4: | B9: 4. The performance measures motivate me to engage in an efficient recovery process? | J9: 1 | K9: 496 | L9: 0.7
A10: Question 5: | B10: 5. The behaviors of the supervisors and managers are consistent with their communication? | J10: 1 | K10: 560 | L10: 0.8
A11: Question 6: | B11: 6. My peers display a mentality that drives cooperation? | J11: 1 | K11: 581 | L11: 0.8
A12: Question 7: | B12: 7. The supervisors and managers provide recognition for improvement/high performance that is meaningful to me? | J12: 1 | K12: 479 | L12: 0.7
A13: Question 8: | B13: 8. The supervisors and managers promote the department’s vision? | J13: 1 | K13: 549 | L13: 0.8
A14: Question 9: | B14: 9. The objectives of the department are clearly defined? | J14: 1 | K14: 546 | L14: 0.8
A15: Question 10: | B15: 10. I am familiar with the vision for the department? | J15: 1 | K15: 585 | L15: 0.8
A16: Question 11: | B16: 11. I understand my role in delivering on the vision of the department? | J16: 1 | K16: 600 | L16: 0.9
A17: Question 12: | B17: 12. I play a meaningful role in the success of the company? | J17: 1 | K17: 637 | L17: 0.9
... A21: Question 16: | B21: 16. The training methods are effective in building new skills? | J21: 1 | K21: 451 | L21: 0.6
I23: Total Scores: | J23: 16 | K23: 8706 | L23: 12.5 | M23: 11216
A25: Survey Statistics
A26: Total Invitations | C26: 1467
A27: Invited Responses | C27: 697
A28: Response Rate | C28: 0.47
A29: Percent Positive | C29: 1
A30: Percent Follow Up | C30: 0
A31: Report Start Date | C31: 01/01/2015
A32: Report End Date | C32: 01/31/2015
A34: Email Address | B34: Date Requested | C34: Work Order | D34: Date Responded | E34: Result | F34: Total Score | G34: Followup | H34: Q1 Answer | I34: Q1 Score | J34: Q2 Answer | K34: Q2 Score | L34: Q3 Answer | M34: Q3 Score | N34: Q4 Answer | O34: Q4 Score | P34: Q5 Answer | Q34: Q5 Score | R34: Q6 Answer | S34: Q6 Score | T34: Q7 Answer | U34: Q7 Score | V34: Q8 Answer | W34: Q8 Score | X34: Q9 Answer | Y34: Q9 Score | Z34: Q10 Answer | AA34: Q10 Score | AB34: Q11 Answer | AC34: Q11 Score | AD34: Q12 Answer | AE34: Q12 Score | AF34: Q13 Answer | AG34: Q13 Score | AH34: Q14 Answer | AI34: Q14 Score | AJ34: Q15 Answer | AK34: Q15 Score | AL34: Q16 Answer | AM34: Q16 Score | AN34: Section 1 Total
A35: NKICCHANNAGA@csc.com | B35: 42033.65 | C35: 0 | D35: 42033.653 | E35: Pos | F35: 8 | G35: No | H35: Yes | I35: 1 | J35: Yes | K35: 1 | L35: No | M35: 0 | N35: No | O35: 0 | P35: No | Q35: 0 | R35: No | S35: 0 | T35: No | U35: 0 | V35: Yes | W35: 1 | X35: No | Y35: 0 | Z35: Yes | AA35: 1 | AB35: Yes | AC35: 1 | AD35: Yes | AE35: 1 | AF35: Yes | AG35: 1 | AH35: No | AI35: 0 | AJ35: Yes | AK35: 1 | AL35: No | AM35: 0 | AN35: 8
A36: LMOLLURU2@CSC.COM | B36: 42033.652 | C36: 0 | D36: 42033.66 | E36: Pos | F36: 13 | G36: No | H36: Yes | I36: 1 | J36: Yes | K36: 1 | L36: Yes | M36: 1 | N36: Yes | O36: 1 | P36: Yes | Q36: 1 | R36: Yes | S36: 1 | T36: Yes | U36: 1 | V36: Yes | W36: 1 | X36: No | Y36: 0 | Z36: Yes | AA36: 1 | AB36: Yes | AC36: 1 | AD36: Yes | AE36: 1 | AF36: No | AG36: 0 | AH36: No | AI36: 0 | AJ36: Yes | AK36: 1 | AL36: Yes | AM36: 1 | AN36: 13
A37: CGALLEGOS2@csc.com | B37: 42033.661 | C37: 0 | D37: 42033.662 | E37: Pos | F37: 9 | G37: No | H37: Yes | I37: 1 | J37: No | K37: 0 | L37: No | M37: 0 | N37: No | O37: 0 | P37: Yes | Q37: 1 | R37: Yes | S37: 1 | T37: No | U37: 0 | V37: Yes | W37: 1 | X37: Yes | Y37: 1 | Z37: Yes | AA37: 1 | AB37: Yes | AC37: 1 | AD37: Yes | AE37: 1 | AF37: No | AG37: 0 | AH37: No | AI37: 0 | AJ37: Yes | AK37: 1 | AL37: No | AM37: 0 | AN37: 9
A38: UMONGA@csc.com | B38: 42033.651 | C38: 0 | D38: 42033.665 | E38: Pos | F38: 16 | G38: No | H38: Yes | I38: 1 | J38: Yes | K38: 1 | L38: Yes | M38: 1 | N38: Yes | O38: 1 | P38: Yes | Q38: 1 | R38: Yes | S38: 1 | T38: Yes | U38: 1 | V38: Yes | W38: 1 | X38: Yes | Y38: 1 | Z38: Yes | AA38: 1 | AB38: Yes | AC38: 1 | AD38: Yes | AE38: 1 | AF38: Yes | AG38: 1 | AH38: Yes | AI38: 1 | AJ38: Yes | AK38: 1 | AL38: Yes | AM38: 1 | AN38: 16
A39: NMANOHARI@csc.com | B39: 42033.653 | C39: 0 | D39: 42033.667 | E39: Pos | F39: 16 | G39: No | H39: Yes | I39: 1 | J39: Yes | K39: 1 | L39: Yes | M39: 1 | N39: Yes | O39: 1 | P39: Yes | Q39: 1 | R39: Yes | S39: 1 | T39: Yes | U39: 1 | V39: Yes | W39: 1 | X39: Yes | Y39: 1 | Z39: Yes | AA39: 1 | AB39: Yes | AC39: 1 | AD39: Yes | AE39: 1 | AF39: Yes | AG39: 1 | AH39: Yes | AI39: 1 | AJ39: Yes | AK39: 1 | AL39: Yes | AM39: 1 | AN39: 16
A40: SBHARTI2@csc.com | B40: 42033.651 | C40: 0 | D40: 42033.667 | E40: Pos | F40: 1 | G40: No | H40: No | I40: 0 | J40: No | K40: 0 | L40: No | M40: 0 | N40: No | O40: 0 | P40: No | Q40: 0 | R40: Yes | S40: 1 | T40: No | U40: 0 | V40: No | W40: 0 | X40: No | Y40: 0 | Z40: No | AA40: 0 | AB40: No | AC40: 0 | AD40: No | AE40: 0 | AF40: No | AG40: 0 | AH40: No | AI40: 0 | AJ40: No | AK40: 0 | AL40: No | AM40: 0 | AN40: 1
A41: SAZHAR@csc.com | B41: 42033.65 | C41: 0 | D41: 42033.668 | E41: Pos | F41: 15 | G41: No | H41: Yes | I41: 1 | J41: Yes | K41: 1 | L41: Yes | M41: 1 | N41: Yes | O41: 1 | P41: Yes | Q41: 1 | R41: Yes | S41: 1 | T41: Yes | U41: 1 | V41: Yes | W41: 1 | X41: Yes | Y41: 1 | Z41: Yes | AA41: 1 | AB41: Yes | AC41: 1 | AD41: Yes | AE41: 1 | AF41: Yes | AG41: 1 | AH41: Yes | AI41: 1 | AJ41: No | AK41: 0 | AL41: Yes | AM41: 1 | AN41: 15
A42: NPEDDI3@CSC.COM | B42: 42033.668 | C42: 0 | D42: 42033.676 | E42: Pos | F42: 16 | G42: No | H42: Yes | I42: 1 | J42: Yes | K42: 1 | L42: Yes | M42: 1 | N42: Yes | O42: 1 | P42: Yes | Q42: 1 | R42: Yes | S42: 1 | T42: Yes | U42: 1 | V42: Yes | W42: 1 | X42: Yes | Y42: 1 | Z42: Yes | AA42: 1 | AB42: Yes | AC42: 1 | AD42: Yes | AE42: 1 | AF42: Yes | AG42: 1 | AH42: Yes | AI42: 1 | AJ42: Yes | AK42: 1 | AL42: Yes | AM42: 1 | AN42: 16
A43: SKOTHURU@csc.com | B43: 42033.669 | C43: 0 | D43: 42033.678 | E43: Pos | F43: 16 | G43: No | H43: Yes | I43: 1 | J43: Yes | K43: 1 | L43: Yes | M43: 1 | N43: Yes | O43: 1 | P43: Yes | Q43: 1 | R43: Yes | S43: 1 | T43: Yes | U43: 1 | V43: Yes | W43: 1 | X43: Yes | Y43: 1 | Z43: Yes | AA43: 1 | AB43: Yes | AC43: 1 | AD43: Yes | AE43: 1 | AF43: Yes | AG43: 1 | AH43: Yes | AI43: 1 | AJ43: Yes | AK43: 1 | AL43: Yes | AM43: 1 | AN43: 16
A44: RVOJJALA@CSC.COM | B44: 42033.667 | C44: 0 | D44: 42033.68 | E44: Pos | F44: 16 | G44: No | H44: Yes | I44: 1 | J44: Yes | K44: 1 | L44: Yes | M44: 1 | N44: Yes | O44: 1 | P44: Yes | Q44: 1 | R44: Yes | S44: 1 | T44: Yes | U44: 1 | V44: Yes | W44: 1 | X44: Yes | Y44: 1 | Z44: Yes | AA44: 1 | AB44: Yes | AC44: 1 | AD44: Yes | AE44: 1 | AF44: Yes | AG44: 1 | AH44: Yes | AI44: 1 | AJ44: Yes | AK44: 1 | AL44: Yes | AM44: 1 | AN44: 16
A45: NASHOKKUMARS@csc.com | B45: 42033.668 | C45: 0 | D45: 42033.68 | E45: Pos | F45: 10 | G45: No | H45: Yes | I45: 1 | J45: No | K45: 0 | L45: No | M45: 0 | N45: No | O45: 0 | P45: Yes | Q45: 1 | R45: Yes | S45: 1 | T45: No | U45: 0 | V45: Yes | W45: 1 | X45: No | Y45: 0 | Z45: Yes | AA45: 1 | AB45: Yes | AC45: 1 | AD45: Yes | AE45: 1 | AF45: Yes | AG45: 1 | AH45: Yes | AI45: 1 | AJ45: Yes | AK45: 1 | AL45: No | AM45: 0 | AN45: 10
A46: KSIDDIQUI5@csc.com | B46: 42033.651 | C46: 0 | D46: 42033.683 | E46: Pos | F46: 15 | G46: No | H46: Yes | I46: 1 | J46: Yes | K46: 1 | L46: Yes | M46: 1 | N46: No | O46: 0 | P46: Yes | Q46: 1 | R46: Yes | S46: 1 | T46: Yes | U46: 1 | V46: Yes | W46: 1 | X46: Yes | Y46: 1 | Z46: Yes | AA46: 1 | AB46: Yes | AC46: 1 | AD46: Yes | AE46: 1 | AF46: Yes | AG46: 1 | AH46: Yes | AI46: 1 | AJ46: Yes | AK46: 1 | AL46: Yes | AM46: 1 | AN46: 15
... A735: VBHARDWAJ3@csc.com | B735: 42048.042 | C735: 0 | D735: 42048.11 | E735: Pos | F735: 16 | G735: No | H735: Yes | I735: 1 | J735: Yes | K735: 1 | L735: Yes | M735: 1 | N735: Yes | O735: 1 | P735: Yes | Q735: 1 | R735: Yes | S735: 1 | T735: Yes | U735: 1 | V735: Yes | W735: 1 | X735: Yes | Y735: 1 | Z735: Yes | AA735: 1 | AB735: Yes | AC735: 1 | AD735: Yes | AE735: 1 | AF735: Yes | AG735: 1 | AH735: Yes | AI735: 1 | AJ735: Yes | AK735: 1 | AL735: Yes | AM735: 1 | AN735: 16

Sheet Compiled Agents
A1: Short ID | B1: LOS | C1: Region | D1: Region 2 | E1: Wave | F1: Color | G1: Email ID | H1: Status
A2: acoppola | B2: Pod Manager | C2: MBC US PW1 | D2: =VLOOKUP(C2,Region!A:B,2,FALSE) -> MBC US | E2: Wave2 | F2: POD Manager | G2: acoppola@csc.com | H2: Completed
A3: agarciagomez | B3: Platform | C3: Spain | D3: =VLOOKUP(C3,Region!A:B,2,FALSE) -> Spain | E3: Wave1 | F3: Orange | G3: agarciagomez@csc.com | H3: Not Completed
A4: agupta312 | B4: Workplace | C4: Hyderabad - WP | D4: =VLOOKUP(C4,Region!A:B,2,FALSE) -> Hyderabad | E4: Wave2 | F4: Blue | G4: agupta312@csc.com | H4: Completed
A5: alafuentesua | B5: Platform | C5: Spain | D5: =VLOOKUP(C5,Region!A:B,2,FALSE) -> Spain | E5: Wave1 | F5: Orange | G5: alafuentesua@csc.com | H5: Not Completed
A6: APALANIAPPAN | B6: Platform | C6: Hyderabad - Platform | D6: =VLOOKUP(C6,Region!A:B,2,FALSE) -> Hyderabad | E6: Wave1 | F6: Orange | G6: APALANIAPPAN@csc.com | H6: Completed
A7: aporwal3 | B7: Workplace | C7: Hyderabad - WP | D7: =VLOOKUP(C7,Region!A:B,2,FALSE) -> Hyderabad | E7: Wave2 | F7: Purple | G7: aporwal3@csc.com | H7: Completed
A8: csharma7 | B8: Platform | C8: Noida PF Wave 2 (Kamal Arora) | D8: =VLOOKUP(C8,Region!A:B,2,FALSE) -> Noida | E8: Wave2 | F8: Yellow | G8: csharma7@csc.com | H8: Not Completed
A9: eashokjain | B9: Platform | C9: Hyderabad - Platform | D9: =VLOOKUP(C9,Region!A:B,2,FALSE) -> Hyderabad | E9: Wave1 | F9: Orange | G9: eashokjain@csc.com | H9: Completed
A10: frodriguezg2 | B10: Platform | C10: Spain | D10: =VLOOKUP(C10,Region!A:B,2,FALSE) -> Spain | E10: Wave1 | F10: Orange | G10: frodriguezg2@csc.com | H10: Not Completed
A11: jbisht | B11: Workplace | C11: Hyderabad - WP | D11: =VLOOKUP(C11,Region!A:B,2,FALSE) -> Hyderabad | E11: Wave2 | F11: Purple | G11: jbisht@csc.com | H11: Not Completed
A12: jmartinezbro | B12: Platform | C12: Spain | D12: =VLOOKUP(C12,Region!A:B,2,FALSE) -> Spain | E12: Wave1 | F12: Orange | G12: jmartinezbro@csc.com | H12: Completed
A13: jrubialgomez | B13: Platform | C13: Spain | D13: =VLOOKUP(C13,Region!A:B,2,FALSE) -> Spain | E13: Wave1 | F13: Orange | G13: jrubialgomez@csc.com | H13: Not Completed
... A678: melango | B678: Workplace | C678: Hyderabad - WP | D678: =VLOOKUP(C678,Region!A:B,2,FALSE) -> Hyderabad | E678: Wave2 | F678: Orange | G678: melango@csc.com | H678: Completed
A679: mencabonavaz | B679: Platform | C679: Spain | D679: =VLOOKUP(C679,Region!A:B,2,FALSE) -> Spain | E679: Wave1 | F679: Purple
A680: mencabonavaz | B680: Platform | C680: Spain | D680: =VLOOKUP(C680,Region!A:B,2,FALSE) -> Spain | E680: Wave1 | F680: Orange | G680: mencabonavaz@csc.com | H680: Completed
A681: mfaizan | B681: Workplace | C681: Noida WP POD 1 | D681: =VLOOKUP(C681,Region!A:B,2,FALSE) -> Noida | E681: Wave1 | F681: Blue | G681: mfaizan@csc.com | H681: Completed
A682: mfernandezan | B682: Workplace | C682: Spain | D682: =VLOOKUP(C682,Region!A:B,2,FALSE) -> Spain | E682: Wave1 | F682: Blue | G682: mfernandezan@csc.com | H682: Not Completed
A683: mfidalgomar2 | B683: Workplace | C683: Spain | D683: =VLOOKUP(C683,Region!A:B,2,FALSE) -> Spain | E683: Wave1 | F683: Blue | G683: mfidalgomar2@csc.com | H683: Not Completed
A684: mfontelafuen | B684: Workplace | C684: Spain | D684: =VLOOKUP(C684,Region!A:B,2,FALSE) -> Spain | E684: Wave1 | F684: Purple | G684: mfontelafuen@csc.com | H684: Not Completed
A685: mgagnon3 | B685: Workplace | C685: Spain | D685: =VLOOKUP(C685,Region!A:B,2,FALSE) -> Spain | E685: Wave1 | F685: Yellow | G685: mgagnon3@csc.com | H685: Not Completed
A686: MGANDHI3 | B686: Platform | C686: Noida PF POD 1 | D686: =VLOOKUP(C686,Region!A:B,2,FALSE) -> Noida | E686: Wave1 | F686: Blue | G686: MGANDHI3@csc.com | H686: Completed
A687: mganji3 | B687: Platform | C687: Noida PF Wave 2 (Kamal Arora) | D687: =VLOOKUP(C687,Region!A:B,2,FALSE) -> Noida | E687: Wave2 | F687: Blue | G687: mganji3@csc.com | H687: Not Completed
A688: mgaur | B688: Platform | C688: Noida PF Wave 2 (Kamal Arora) | D688: =VLOOKUP(C688,Region!A:B,2,FALSE) -> Noida | E688: Wave2 | F688: Blue | G688: mgaur@csc.com | H688: Completed
A689: mglanovsky | B689: Platform | C689: MBC US PW1 | D689: =VLOOKUP(C689,Region!A:B,2,FALSE) -> MBC US | E689: Wave2 | F689: Orange | G689: mglanovsky@csc.com | H689: Not Completed
A690: mgonzalez30 | B690: Workplace | C690: MBC US PW1 | D690: =VLOOKUP(C690,Region!A:B,2,FALSE) -> MBC US | E690: Wave2 | F690: Yellow | G690: mgonzalez30@csc.com | H690: Completed
A691: mgupta48 | B691: Platform | C691: Noida POD2 | D691: =VLOOKUP(C691,Region!A:B,2,FALSE) -> Noida | E691: Wave2 | F691: Brown | G691: mgupta48@csc.com | H691: Completed
... A1036: rsadanandan | B1036: Workplace | C1036: Noida WP POD 2 | D1036: =VLOOKUP(C1036,Region!A:B,2,FALSE) -> Noida | E1036: Wave2 | F1036: Purple | G1036: rsadanandan@csc.com | H1036: Completed
A1037: RSAHU9 | B1037: Workplace | C1037: Noida WP POD 2 | D1037: =VLOOKUP(C1037,Region!A:B,2,FALSE) -> Noida | E1037: Wave2 | F1037: Yellow
A1038: rsahu9 | B1038: Workplace | C1038: Noida WP POD 2 | D1038: =VLOOKUP(C1038,Region!A:B,2,FALSE) -> Noida | E1038: Wave2 | F1038: Purple | G1038: rsahu9@csc.com | H1038: Completed
A1039: rsaicharan | B1039: Platform | C1039: Noida PF POD 1 | D1039: =VLOOKUP(C1039,Region!A:B,2,FALSE) -> Noida | E1039: Wave1 | F1039: Yellow | G1039: rsaicharan@csc.com | H1039: Not Completed
A1040: RSAINI8 | B1040: Workplace | C1040: Noida WP POD 1 | D1040: =VLOOKUP(C1040,Region!A:B,2,FALSE) -> Noida | E1040: Wave1 | F1040: Orange | G1040: RSAINI8@csc.com | H1040: Not Completed
A1041: rsainzpando | B1041: Platform | C1041: Spain | D1041: =VLOOKUP(C1041,Region!A:B,2,FALSE) -> Spain | E1041: Wave1 | F1041: Blue | G1041: rsainzpando@csc.com | H1041: Completed
A1042: RSAMPATH5 | B1042: Platform | C1042: Hyderabad - Platform | D1042: =VLOOKUP(C1042,Region!A:B,2,FALSE) -> Hyderabad | E1042: Wave1 | F1042: Blue | G1042: RSAMPATH5@csc.com | H1042: Not Completed
A1043: rsanzperez | B1043: Platform | C1043: Spain | D1043: =VLOOKUP(C1043,Region!A:B,2,FALSE) -> Spain | E1043: Wave1 | F1043: Purple | G1043: rsanzperez@csc.com | H1043: Completed
A1044: RSELVARAJ22 | B1044: Platform | C1044: Noida PF POD 1 | D1044: =VLOOKUP(C1044,Region!A:B,2,FALSE) -> Noida | E1044: Wave1 | F1044: Yellow | G1044: RSELVARAJ22@csc.com | H1044: Completed
A1045: RSETH7 | B1045: Workplace | C1045: Noida WP POD 2 | D1045: =VLOOKUP(C1045,Region!A:B,2,FALSE) -> Noida | E1045: Wave2 | F1045: Purple | G1045: RSETH7@csc.com | H1045: Not Completed
A1046: rsharier | B1046: Platform | C1046: MBC US PW1 | D1046: =VLOOKUP(C1046,Region!A:B,2,FALSE) -> MBC US | E1046: Wave2 | F1046: Orange | G1046: rsharier@csc.com | H1046: Completed
A1047: rsharma225 | B1047: Platform | C1047: Noida POD2 | D1047: =VLOOKUP(C1047,Region!A:B,2,FALSE) -> Noida | E1047: Wave2 | F1047: Yellow | G1047: rsharma225@csc.com | H1047: Not Completed
A1048: rsingaraj | B1048: Workplace | C1048: Hyderabad - WP | D1048: =VLOOKUP(C1048,Region!A:B,2,FALSE) -> Hyderabad | E1048: Wave2 | F1048: Purple | G1048: rsingaraj@csc.com | H1048: Not Completed
...

Sheet Region
A1: MBC US PW1 | B1: MBC US
A2: Hyderabad - Platform | B2: Hyderabad
A3: Hyderabad - WP | B3: Hyderabad
A4: Noida PF POD 1 | B4: Noida
A5: Noida PF Wave 2 (Kamal Arora) | B5: Noida
A6: Noida POD2 | B6: Noida
A7: Noida WP POD 1 | B7: Noida
A8: Noida WP POD 2 | B8: Noida
A9: Spain | B9: Spain

Sheet Raw
A1: Email Address | B1: ShortID | C1: LOS | D1: Region | E1: Wave | F1: Color | G1: Total Score | H1: Q1 | I1: Q2 | J1: Q3 | K1: Q4 | L1: Q5 | M1: Q6 | N1: Q7 | O1: Q8 | P1: Q9 | Q1: Q10 | R1: Q11 | S1: Q12 | T1: Q13 | U1: Q14 | V1: Q15 | W1: Q16
A2: NKICCHANNAGA@csc.com | B2: =TRIM(LEFT(A2,FIND("@",A2)-1)) -> NKICCHANNAGA | C2: =VLOOKUP(B2,'Compiled Agents'!A:H,2,FALSE) -> Platform | D2: =VLOOKUP(B2,'Compiled Agents'!A:H,4,FALSE) -> Noida | E2: =VLOOKUP(B2,'Compiled Agents'!A:H,5,FALSE) -> Wave2 | F2: =VLOOKUP(B2,'Compiled Agents'!A:H,6,FALSE) -> Purple | G2: =VLOOKUP($A2,'SurveyRpt_20150223 (1)'!$A$34:$AN$735,6,FALSE) -> 8 | H2: =VLOOKUP($A2,'SurveyRpt_20150223 (1)'!$A$34:$AN$735,8,FALSE) -> Yes | I2: =VLOOKUP($A2,'SurveyRpt_20150223 (1)'!$A$34:$AN$735,10,FALSE) -> Yes | J2: =VLOOKUP($A2,'SurveyRpt_20150223 (1)'!$A$34:$AN$735,12,FALSE) -> No | K2: =VLOOKUP($A2,'SurveyRpt_20150223 (1)'!$A$34:$AN$735,14,FALSE) -> No | L2: =VLOOKUP($A2,'SurveyRpt_20150223 (1)'!$A$34:$AN$735,16,FALSE) -> No | M2: =VLOOKUP($A2,'SurveyRpt_20150223 (1)'!$A$34:$AN$735,18,FALSE) -> No | N2: =VLOOKUP($A2,'SurveyRpt_20150223 (1)'!$A$34:$AN$735,20,FALSE) -> No | O2: =VLOOKUP($A2,'SurveyRpt_20150223 (1)'!$A$34:$AN$735,22,FALSE) -> Yes | P2: =VLOOKUP($A2,'SurveyRpt_20150223 (1)'!$A$34:$AN$735,24,FALSE) -> No | Q2: =VLOOKUP($A2,'SurveyRpt_20150223 (1)'!$A$34:$AN$735,26,FALSE) -> Yes | R2: =VLOOKUP($A2,'SurveyRpt_20150223 (1)'!$A$34:$AN$735,28,FALSE) -> Yes | S2: =VLOOKUP($A2,'SurveyRpt_20150223 (1)'!$A$34:$AN$735,30,FALSE) -> Yes | T2: =VLOOKUP($A2,'SurveyRpt_20150223 (1)'!$A$34:$AN$735,32,FALSE) -> Yes | U2: =VLOOKUP($A2,'SurveyRpt_20150223 (1)'!$A$34:$AN$735,34,FALSE) -> No | V2: =VLOOKUP($A2,'SurveyRpt_20150223 (1)'!$A$34:$AN$735,36,FALSE) -> Yes | W2: =VLOOKUP($A2,'SurveyRpt_20150223 (1)'!$A$34:$AN$735,38,FALSE) -> No
A3: LMOLLURU2@CSC.COM | B3: =TRIM(LEFT(A3,FIND("@",A3)-1)) -> LMOLLURU2 | C3: =VLOOKUP(B3,'Compiled Agents'!A:H,2,FALSE) -> Platform | D3: =VLOOKUP(B3,'Compiled Agents'!A:H,4,FALSE) -> Noida | E3: =VLOOKUP(B3,'Compiled Agents'!A:H,5,FALSE) -> Wave2 | F3: =VLOOKUP(B3,'Compiled Agents'!A:H,6,FALSE) -> Orange | G3: =VLOOKUP($A3,'SurveyRpt_20150223 (1)'!$A$34:$AN$735,6,FALSE) -> 13 | H3: =VLOOKUP($A3,'SurveyRpt_20150223 (1)'!$A$34:$AN$735,8,FALSE) -> Yes | I3: =VLOOKUP($A3,'SurveyRpt_20150223 (1)'!$A$34:$AN$735,10,FALSE) -> Yes | J3: =VLOOKUP($A3,'SurveyRpt_20150223 (1)'!$A$34:$AN$735,12,FALSE) -> Yes | K3: =VLOOKUP($A3,'SurveyRpt_20150223 (1)'!$A$34:$AN$735,14,FALSE) -> Yes | L3: =VLOOKUP($A3,'SurveyRpt_20150223 (1)'!$A$34:$AN$735,16,FALSE) -> Yes | M3: =VLOOKUP($A3,'SurveyRpt_20150223 (1)'!$A$34:$AN$735,18,FALSE) -> Yes | N3: =VLOOKUP($A3,'SurveyRpt_20150223 (1)'!$A$34:$AN$735,20,FALSE) -> Yes | O3: =VLOOKUP($A3,'SurveyRpt_20150223 (1)'!$A$34:$AN$735,22,FALSE) -> Yes | P3: =VLOOKUP($A3,'SurveyRpt_20150223 (1)'!$A$34:$AN$735,24,FALSE) -> No | Q3: =VLOOKUP($A3,'SurveyRpt_20150223 (1)'!$A$34:$AN$735,26,FALSE) -> Yes | R3: =VLOOKUP($A3,'SurveyRpt_20150223 (1)'!$A$34:$AN$735,28,FALSE) -> Yes | S3: =VLOOKUP($A3,'SurveyRpt_20150223 (1)'!$A$34:$AN$735,30,FALSE) -> Yes | T3: =VLOOKUP($A3,'SurveyRpt_20150223 (1)'!$A$34:$AN$735,32,FALSE) -> No | U3: =VLOOKUP($A3,'SurveyRpt_20150223 (1)'!$A$34:$AN$735,34,FALSE) -> No | V3: =VLOOKUP($A3,'SurveyRpt_20150223 (1)'!$A$34:$AN$735,36,FALSE) -> Yes | W3: =VLOOKUP($A3,'SurveyRpt_20150223 (1)'!$A$34:$AN$735,38,FALSE) -> Yes
A4: CGALLEGOS2@csc.com | B4: =TRIM(LEFT(A4,FIND("@",A4)-1)) -> CGALLEGOS2 | C4: =VLOOKUP(B4,'Compiled Agents'!A:H,2,FALSE) -> Workplace | D4: =VLOOKUP(B4,'Compiled Agents'!A:H,4,FALSE) -> MBC US | E4: =VLOOKUP(B4,'Compiled Agents'!A:H,5,FALSE) -> Wave2 | F4: =VLOOKUP(B4,'Compiled Agents'!A:H,6,FALSE) -> Yellow | G4: =VLOOKUP($A4,'SurveyRpt_20150223 (1)'!$A$34:$AN$735,6,FALSE) -> 9 | H4: =VLOOKUP($A4,'SurveyRpt_20150223 (1)'!$A$34:$AN$735,8,FALSE) -> Yes | I4: =VLOOKUP($A4,'SurveyRpt_20150223 (1)'!$A$34:$AN$735,10,FALSE) -> No | J4: =VLOOKUP($A4,'SurveyRpt_20150223 (1)'!$A$34:$AN$735,12,FALSE) -> No | K4: =VLOOKUP($A4,'SurveyRpt_20150223 (1)'!$A$34:$AN$735,14,FALSE) -> No | L4: =VLOOKUP($A4,'SurveyRpt_20150223 (1)'!$A$34:$AN$735,16,FALSE) -> Yes | M4: =VLOOKUP($A4,'SurveyRpt_20150223 (1)'!$A$34:$AN$735,18,FALSE) -> Yes | N4: =VLOOKUP($A4,'SurveyRpt_20150223 (1)'!$A$34:$AN$735,20,FALSE) -> No | O4: =VLOOKUP($A4,'SurveyRpt_20150223 (1)'!$A$34:$AN$735,22,FALSE) -> Yes | P4: =VLOOKUP($A4,'SurveyRpt_20150223 (1)'!$A$34:$AN$735,24,FALSE) -> Yes | Q4: =VLOOKUP($A4,'SurveyRpt_20150223 (1)'!$A$34:$AN$735,26,FALSE) -> Yes | R4: =VLOOKUP($A4,'SurveyRpt_20150223 (1)'!$A$34:$AN$735,28,FALSE) -> Yes | S4: =VLOOKUP($A4,'SurveyRpt_20150223 (1)'!$A$34:$AN$735,30,FALSE) -> Yes | T4: =VLOOKUP($A4,'SurveyRpt_20150223 (1)'!$A$34:$AN$735,32,FALSE) -> No | U4: =VLOOKUP($A4,'SurveyRpt_20150223 (1)'!$A$34:$AN$735,34,FALSE) -> No | V4: =VLOOKUP($A4,'SurveyRpt_20150223 (1)'!$A$34:$AN$735,36,FALSE) -> Yes | W4: =VLOOKUP($A4,'SurveyRpt_20150223 (1)'!$A$34:$AN$735,38,FALSE) -> No
A5: UMONGA@csc.com | B5: =TRIM(LEFT(A5,FIND("@",A5)-1)) -> UMONGA | C5: =VLOOKUP(B5,'Compiled Agents'!A:H,2,FALSE) -> Platform | D5: =VLOOKUP(B5,'Compiled Agents'!A:H,4,FALSE) -> Noida | E5: =VLOOKUP(B5,'Compiled Agents'!A:H,5,FALSE) -> Wave2 | F5: =VLOOKUP(B5,'Compiled Agents'!A:H,6,FALSE) -> Yellow | G5: =VLOOKUP($A5,'SurveyRpt_20150223 (1)'!$A$34:$AN$735,6,FALSE) -> 16 | H5: =VLOOKUP($A5,'SurveyRpt_20150223 (1)'!$A$34:$AN$735,8,FALSE) -> Yes | I5: =VLOOKUP($A5,'SurveyRpt_20150223 (1)'!$A$34:$AN$735,10,FALSE) -> Yes | J5: =VLOOKUP($A5,'SurveyRpt_20150223 (1)'!$A$34:$AN$735,12,FALSE) -> Yes | K5: =VLOOKUP($A5,'SurveyRpt_20150223 (1)'!$A$34:$AN$735,14,FALSE) -> Yes | L5: =VLOOKUP($A5,'SurveyRpt_20150223 (1)'!$A$34:$AN$735,16,FALSE) -> Yes | M5: =VLOOKUP($A5,'SurveyRpt_20150223 (1)'!$A$34:$AN$735,18,FALSE) -> Yes | N5: =VLOOKUP($A5,'SurveyRpt_20150223 (1)'!$A$34:$AN$735,20,FALSE) -> Yes | O5: =VLOOKUP($A5,'SurveyRpt_20150223 (1)'!$A$34:$AN$735,22,FALSE) -> Yes | P5: =VLOOKUP($A5,'SurveyRpt_20150223 (1)'!$A$34:$AN$735,24,FALSE) -> Yes | Q5: =VLOOKUP($A5,'SurveyRpt_20150223 (1)'!$A$34:$AN$735,26,FALSE) -> Yes | R5: =VLOOKUP($A5,'SurveyRpt_20150223 (1)'!$A$34:$AN$735,28,FALSE) -> Yes | S5: =VLOOKUP($A5,'SurveyRpt_20150223 (1)'!$A$34:$AN$735,30,FALSE) -> Yes | T5: =VLOOKUP($A5,'SurveyRpt_20150223 (1)'!$A$34:$AN$735,32,FALSE) -> Yes | U5: =VLOOKUP($A5,'SurveyRpt_20150223 (1)'!$A$34:$AN$735,34,FALSE) -> Yes | V5: =VLOOKUP($A5,'SurveyRpt_20150223 (1)'!$A$34:$AN$735,36,FALSE) -> Yes | W5: =VLOOKUP($A5,'SurveyRpt_20150223 (1)'!$A$34:$AN$735,38,FALSE) -> Yes
A6: NMANOHARI@csc.com | B6: =TRIM(LEFT(A6,FIND("@",A6)-1)) -> NMANOHARI | C6: =VLOOKUP(B6,'Compiled Agents'!A:H,2,FALSE) -> Workplace | D6: =VLOOKUP(B6,'Compiled Agents'!A:H,4,FALSE) -> Hyderabad | E6: =VLOOKUP(B6,'Compiled Agents'!A:H,5,FALSE) -> Wave2 | F6: =VLOOKUP(B6,'Compiled Agents'!A:H,6,FALSE) -> Yellow | G6: =VLOOKUP($A6,'SurveyRpt_20150223 (1)'!$A$34:$AN$735,6,FALSE) -> 16 | H6: =VLOOKUP($A6,'SurveyRpt_20150223 (1)'!$A$34:$AN$735,8,FALSE) -> Yes | I6: =VLOOKUP($A6,'SurveyRpt_20150223 (1)'!$A$34:$AN$735,10,FALSE) -> Yes | J6: =VLOOKUP($A6,'SurveyRpt_20150223 (1)'!$A$34:$AN$735,12,FALSE) -> Yes | K6: =VLOOKUP($A6,'SurveyRpt_20150223 (1)'!$A$34:$AN$735,14,FALSE) -> Yes | L6: =VLOOKUP($A6,'SurveyRpt_20150223 (1)'!$A$34:$AN$735,16,FALSE) -> Yes | M6: =VLOOKUP($A6,'SurveyRpt_20150223 (1)'!$A$34:$AN$735,18,FALSE) -> Yes | N6: =VLOOKUP($A6,'SurveyRpt_20150223 (1)'!$A$34:$AN$735,20,FALSE) -> Yes | O6: =VLOOKUP($A6,'SurveyRpt_20150223 (1)'!$A$34:$AN$735,22,FALSE) -> Yes | P6: =VLOOKUP($A6,'SurveyRpt_20150223 (1)'!$A$34:$AN$735,24,FALSE) -> Yes | Q6: =VLOOKUP($A6,'SurveyRpt_20150223 (1)'!$A$34:$AN$735,26,FALSE) -> Yes | R6: =VLOOKUP($A6,'SurveyRpt_20150223 (1)'!$A$34:$AN$735,28,FALSE) -> Yes | S6: =VLOOKUP($A6,'SurveyRpt_20150223 (1)'!$A$34:$AN$735,30,FALSE) -> Yes | T6: =VLOOKUP($A6,'SurveyRpt_20150223 (1)'!$A$34:$AN$735,32,FALSE) -> Yes | U6: =VLOOKUP($A6,'SurveyRpt_20150223 (1)'!$A$34:$AN$735,34,FALSE) -> Yes | V6: =VLOOKUP($A6,'SurveyRpt_20150223 (1)'!$A$34:$AN$735,36,FALSE) -> Yes | W6: =VLOOKUP($A6,'SurveyRpt_20150223 (1)'!$A$34:$AN$735,38,FALSE) -> Yes
A7: SBHARTI2@csc.com | B7: =TRIM(LEFT(A7,FIND("@",A7)-1)) -> SBHARTI2 | C7: =VLOOKUP(B7,'Compiled Agents'!A:H,2,FALSE) -> Platform | D7: =VLOOKUP(B7,'Compiled Agents'!A:H,4,FALSE) -> Noida | E7: =VLOOKUP(B7,'Compiled Agents'!A:H,5,FALSE) -> Wave2 | F7: =VLOOKUP(B7,'Compiled Agents'!A:H,6,FALSE) -> Purple | G7: =VLOOKUP($A7,'SurveyRpt_20150223 (1)'!$A$34:$AN$735,6,FALSE) -> 1 | H7: =VLOOKUP($A7,'SurveyRpt_20150223 (1)'!$A$34:$AN$735,8,FALSE) -> No | I7: =VLOOKUP($A7,'SurveyRpt_20150223 (1)'!$A$34:$AN$735,10,FALSE) -> No | J7: =VLOOKUP($A7,'SurveyRpt_20150223 (1)'!$A$34:$AN$735,12,FALSE) -> No | K7: =VLOOKUP($A7,'SurveyRpt_20150223 (1)'!$A$34:$AN$735,14,FALSE) -> No | L7: =VLOOKUP($A7,'SurveyRpt_20150223 (1)'!$A$34:$AN$735,16,FALSE) -> No | M7: =VLOOKUP($A7,'SurveyRpt_20150223 (1)'!$A$34:$AN$735,18,FALSE) -> Yes | N7: =VLOOKUP($A7,'SurveyRpt_20150223 (1)'!$A$34:$AN$735,20,FALSE) -> No | O7: =VLOOKUP($A7,'SurveyRpt_20150223 (1)'!$A$34:$AN$735,22,FALSE) -> No | P7: =VLOOKUP($A7,'SurveyRpt_20150223 (1)'!$A$34:$AN$735,24,FALSE) -> No | Q7: =VLOOKUP($A7,'SurveyRpt_20150223 (1)'!$A$34:$AN$735,26,FALSE) -> No | R7: =VLOOKUP($A7,'SurveyRpt_20150223 (1)'!$A$34:$AN$735,28,FALSE) -> No | S7: =VLOOKUP($A7,'SurveyRpt_20150223 (1)'!$A$34:$AN$735,30,FALSE) -> No | T7: =VLOOKUP($A7,'SurveyRpt_20150223 (1)'!$A$34:$AN$735,32,FALSE) -> No | U7: =VLOOKUP($A7,'SurveyRpt_20150223 (1)'!$A$34:$AN$735,34,FALSE) -> No | V7: =VLOOKUP($A7,'SurveyRpt_20150223 (1)'!$A$34:$AN$735,36,FALSE) -> No | W7: =VLOOKUP($A7,'SurveyRpt_20150223 (1)'!$A$34:$AN$735,38,FALSE) -> No
A8: SAZHAR@csc.com | B8: =TRIM(LEFT(A8,FIND("@",A8)-1)) -> SAZHAR | C8: =VLOOKUP(B8,'Compiled Agents'!A:H,2,FALSE) -> Platform | D8: =VLOOKUP(B8,'Compiled Agents'!A:H,4,FALSE) -> Noida | E8: =VLOOKUP(B8,'Compiled Agents'!A:H,5,FALSE) -> Wave2 | F8: =VLOOKUP(B8,'Compiled Agents'!A:H,6,FALSE) -> Yellow | G8: =VLOOKUP($A8,'SurveyRpt_20150223 (1)'!$A$34:$AN$735,6,FALSE) -> 15 | H8: =VLOOKUP($A8,'SurveyRpt_20150223 (1)'!$A$34:$AN$735,8,FALSE) -> Yes | I8: =VLOOKUP($A8,'SurveyRpt_20150223 (1)'!$A$34:$AN$735,10,FALSE) -> Yes | J8: =VLOOKUP($A8,'SurveyRpt_20150223 (1)'!$A$34:$AN$735,12,FALSE) -> Yes | K8: =VLOOKUP($A8,'SurveyRpt_20150223 (1)'!$A$34:$AN$735,14,FALSE) -> Yes | L8: =VLOOKUP($A8,'SurveyRpt_20150223 (1)'!$A$34:$AN$735,16,FALSE) -> Yes | M8: =VLOOKUP($A8,'SurveyRpt_20150223 (1)'!$A$34:$AN$735,18,FALSE) -> Yes | N8: =VLOOKUP($A8,'SurveyRpt_20150223 (1)'!$A$34:$AN$735,20,FALSE) -> Yes | O8: =VLOOKUP($A8,'SurveyRpt_20150223 (1)'!$A$34:$AN$735,22,FALSE) -> Yes | P8: =VLOOKUP($A8,'SurveyRpt_20150223 (1)'!$A$34:$AN$735,24,FALSE) -> Yes | Q8: =VLOOKUP($A8,'SurveyRpt_20150223 (1)'!$A$34:$AN$735,26,FALSE) -> Yes | R8: =VLOOKUP($A8,'SurveyRpt_20150223 (1)'!$A$34:$AN$735,28,FALSE) -> Yes | S8: =VLOOKUP($A8,'SurveyRpt_20150223 (1)'!$A$34:$AN$735,30,FALSE) -> Yes | T8: =VLOOKUP($A8,'SurveyRpt_20150223 (1)'!$A$34:$AN$735,32,FALSE) -> Yes | U8: =VLOOKUP($A8,'SurveyRpt_20150223 (1)'!$A$34:$AN$735,34,FALSE) -> Yes | V8: =VLOOKUP($A8,'SurveyRpt_20150223 (1)'!$A$34:$AN$735,36,FALSE) -> No | W8: =VLOOKUP($A8,'SurveyRpt_20150223 (1)'!$A$34:$AN$735,38,FALSE) -> Yes
A9: NPEDDI3@CSC.COM | B9: =TRIM(LEFT(A9,FIND("@",A9)-1)) -> NPEDDI3 | C9: =VLOOKUP(B9,'Compiled Agents'!A:H,2,FALSE) -> Platform | D9: =VLOOKUP(B9,'Compiled Agents'!A:H,4,FALSE) -> Hyderabad | E9: =VLOOKUP(B9,'Compiled Agents'!A:H,5,FALSE) -> Wave1 | F9: =VLOOKUP(B9,'Compiled Agents'!A:H,6,FALSE) -> Purple | G9: =VLOOKUP($A9,'SurveyRpt_20150223 (1)'!$A$34:$AN$735,6,FALSE) -> 16 | H9: =VLOOKUP($A9,'SurveyRpt_20150223 (1)'!$A$34:$AN$735,8,FALSE) -> Yes | I9: =VLOOKUP($A9,'SurveyRpt_20150223 (1)'!$A$34:$AN$735,10,FALSE) -> Yes | J9: =VLOOKUP($A9,'SurveyRpt_20150223 (1)'!$A$34:$AN$735,12,FALSE) -> Yes | K9: =VLOOKUP($A9,'SurveyRpt_20150223 (1)'!$A$34:$AN$735,14,FALSE) -> Yes | L9: =VLOOKUP($A9,'SurveyRpt_20150223 (1)'!$A$34:$AN$735,16,FALSE) -> Yes | M9: =VLOOKUP($A9,'SurveyRpt_20150223 (1)'!$A$34:$AN$735,18,FALSE) -> Yes | N9: =VLOOKUP($A9,'SurveyRpt_20150223 (1)'!$A$34:$AN$735,20,FALSE) -> Yes | O9: =VLOOKUP($A9,'SurveyRpt_20150223 (1)'!$A$34:$AN$735,22,FALSE) -> Yes | P9: =VLOOKUP($A9,'SurveyRpt_20150223 (1)'!$A$34:$AN$735,24,FALSE) -> Yes | Q9: =VLOOKUP($A9,'SurveyRpt_20150223 (1)'!$A$34:$AN$735,26,FALSE) -> Yes | R9: =VLOOKUP($A9,'SurveyRpt_20150223 (1)'!$A$34:$AN$735,28,FALSE) -> Yes | S9: =VLOOKUP($A9,'SurveyRpt_20150223 (1)'!$A$34:$AN$735,30,FALSE) -> Yes | T9: =VLOOKUP($A9,'SurveyRpt_20150223 (1)'!$A$34:$AN$735,32,FALSE) -> Yes | U9: =VLOOKUP($A9,'SurveyRpt_20150223 (1)'!$A$34:$AN$735,34,FALSE) -> Yes | V9: =VLOOKUP($A9,'SurveyRpt_20150223 (1)'!$A$34:$AN$735,36,FALSE) -> Yes | W9: =VLOOKUP($A9,'SurveyRpt_20150223 (1)'!$A$34:$AN$735,38,FALSE) -> Yes
A10: SKOTHURU@csc.com | B10: =TRIM(LEFT(A10,FIND("@",A10)-1)) -> SKOTHURU | C10: =VLOOKUP(B10,'Compiled Agents'!A:H,2,FALSE) -> Platform | D10: =VLOOKUP(B10,'Compiled Agents'!A:H,4,FALSE) -> Hyderabad | E10: =VLOOKUP(B10,'Compiled Agents'!A:H,5,FALSE) -> Wave1 | F10: =VLOOKUP(B10,'Compiled Agents'!A:H,6,FALSE) -> Purple | G10: =VLOOKUP($A10,'SurveyRpt_20150223 (1)'!$A$34:$AN$735,6,FALSE) -> 16 | H10: =VLOOKUP($A10,'SurveyRpt_20150223 (1)'!$A$34:$AN$735,8,FALSE) -> Yes | I10: =VLOOKUP($A10,'SurveyRpt_20150223 (1)'!$A$34:$AN$735,10,FALSE) -> Yes | J10: =VLOOKUP($A10,'SurveyRpt_20150223 (1)'!$A$34:$AN$735,12,FALSE) -> Yes | K10: =VLOOKUP($A10,'SurveyRpt_20150223 (1)'!$A$34:$AN$735,14,FALSE) -> Yes | L10: =VLOOKUP($A10,'SurveyRpt_20150223 (1)'!$A$34:$AN$735,16,FALSE) -> Yes | M10: =VLOOKUP($A10,'SurveyRpt_20150223 (1)'!$A$34:$AN$735,18,FALSE) -> Yes | N10: =VLOOKUP($A10,'SurveyRpt_20150223 (1)'!$A$34:$AN$735,20,FALSE) -> Yes | O10: =VLOOKUP($A10,'SurveyRpt_20150223 (1)'!$A$34:$AN$735,22,FALSE) -> Yes | P10: =VLOOKUP($A10,'SurveyRpt_20150223 (1)'!$A$34:$AN$735,24,FALSE) -> Yes | Q10: =VLOOKUP($A10,'SurveyRpt_20150223 (1)'!$A$34:$AN$735,26,FALSE) -> Yes | R10: =VLOOKUP($A10,'SurveyRpt_20150223 (1)'!$A$34:$AN$735,28,FALSE) -> Yes | S10: =VLOOKUP($A10,'SurveyRpt_20150223 (1)'!$A$34:$AN$735,30,FALSE) -> Yes | T10: =VLOOKUP($A10,'SurveyRpt_20150223 (1)'!$A$34:$AN$735,32,FALSE) -> Yes | U10: =VLOOKUP($A10,'SurveyRpt_20150223 (1)'!$A$34:$AN$735,34,FALSE) -> Yes | V10: =VLOOKUP($A10,'SurveyRpt_20150223 (1)'!$A$34:$AN$735,36,FALSE) -> Yes | W10: =VLOOKUP($A10,'SurveyRpt_20150223 (1)'!$A$34:$AN$735,38,FALSE) -> Yes
A11: RVOJJALA@CSC.COM | B11: =TRIM(LEFT(A11,FIND("@",A11)-1)) -> RVOJJALA | C11: =VLOOKUP(B11,'Compiled Agents'!A:H,2,FALSE) -> Platform | D11: =VLOOKUP(B11,'Compiled Agents'!A:H,4,FALSE) -> Hyderabad | E11: =VLOOKUP(B11,'Compiled Agents'!A:H,5,FALSE) -> Wave1 | F11: =VLOOKUP(B11,'Compiled Agents'!A:H,6,FALSE) -> Yellow | G11: =VLOOKUP($A11,'SurveyRpt_20150223 (1)'!$A$34:$AN$735,6,FALSE) -> 16 | H11: =VLOOKUP($A11,'SurveyRpt_20150223 (1)'!$A$34:$AN$735,8,FALSE) -> Yes | I11: =VLOOKUP($A11,'SurveyRpt_20150223 (1)'!$A$34:$AN$735,10,FALSE) -> Yes | J11: =VLOOKUP($A11,'SurveyRpt_20150223 (1)'!$A$34:$AN$735,12,FALSE) -> Yes | K11: =VLOOKUP($A11,'SurveyRpt_20150223 (1)'!$A$34:$AN$735,14,FALSE) -> Yes | L11: =VLOOKUP($A11,'SurveyRpt_20150223 (1)'!$A$34:$AN$735,16,FALSE) -> Yes | M11: =VLOOKUP($A11,'SurveyRpt_20150223 (1)'!$A$34:$AN$735,18,FALSE) -> Yes | N11: =VLOOKUP($A11,'SurveyRpt_20150223 (1)'!$A$34:$AN$735,20,FALSE) -> Yes | O11: =VLOOKUP($A11,'SurveyRpt_20150223 (1)'!$A$34:$AN$735,22,FALSE) -> Yes | P11: =VLOOKUP($A11,'SurveyRpt_20150223 (1)'!$A$34:$AN$735,24,FALSE) -> Yes | Q11: =VLOOKUP($A11,'SurveyRpt_20150223 (1)'!$A$34:$AN$735,26,FALSE) -> Yes | R11: =VLOOKUP($A11,'SurveyRpt_20150223 (1)'!$A$34:$AN$735,28,FALSE) -> Yes | S11: =VLOOKUP($A11,'SurveyRpt_20150223 (1)'!$A$34:$AN$735,30,FALSE) -> Yes | T11: =VLOOKUP($A11,'SurveyRpt_20150223 (1)'!$A$34:$AN$735,32,FALSE) -> Yes | U11: =VLOOKUP($A11,'SurveyRpt_20150223 (1)'!$A$34:$AN$735,34,FALSE) -> Yes | V11: =VLOOKUP($A11,'SurveyRpt_20150223 (1)'!$A$34:$AN$735,36,FALSE) -> Yes | W11: =VLOOKUP($A11,'SurveyRpt_20150223 (1)'!$A$34:$AN$735,38,FALSE) -> Yes
A12: NASHOKKUMARS@csc.com | B12: =TRIM(LEFT(A12,FIND("@",A12)-1)) -> NASHOKKUMARS | C12: =VLOOKUP(B12,'Compiled Agents'!A:H,2,FALSE) -> Platform | D12: =VLOOKUP(B12,'Compiled Agents'!A:H,4,FALSE) -> Hyderabad | E12: =VLOOKUP(B12,'Compiled Agents'!A:H,5,FALSE) -> Wave1 | F12: =VLOOKUP(B12,'Compiled Agents'!A:H,6,FALSE) -> Purple | G12: =VLOOKUP($A12,'SurveyRpt_20150223 (1)'!$A$34:$AN$735,6,FALSE) -> 10 | H12: =VLOOKUP($A12,'SurveyRpt_20150223 (1)'!$A$34:$AN$735,8,FALSE) -> Yes | I12: =VLOOKUP($A12,'SurveyRpt_20150223 (1)'!$A$34:$AN$735,10,FALSE) -> No | J12: =VLOOKUP($A12,'SurveyRpt_20150223 (1)'!$A$34:$AN$735,12,FALSE) -> No | K12: =VLOOKUP($A12,'SurveyRpt_20150223 (1)'!$A$34:$AN$735,14,FALSE) -> No | L12: =VLOOKUP($A12,'SurveyRpt_20150223 (1)'!$A$34:$AN$735,16,FALSE) -> Yes | M12: =VLOOKUP($A12,'SurveyRpt_20150223 (1)'!$A$34:$AN$735,18,FALSE) -> Yes | N12: =VLOOKUP($A12,'SurveyRpt_20150223 (1)'!$A$34:$AN$735,20,FALSE) -> No | O12: =VLOOKUP($A12,'SurveyRpt_20150223 (1)'!$A$34:$AN$735,22,FALSE) -> Yes | P12: =VLOOKUP($A12,'SurveyRpt_20150223 (1)'!$A$34:$AN$735,24,FALSE) -> No | Q12: =VLOOKUP($A12,'SurveyRpt_20150223 (1)'!$A$34:$AN$735,26,FALSE) -> Yes | R12: =VLOOKUP($A12,'SurveyRpt_20150223 (1)'!$A$34:$AN$735,28,FALSE) -> Yes | S12: =VLOOKUP($A12,'SurveyRpt_20150223 (1)'!$A$34:$AN$735,30,FALSE) -> Yes | T12: =VLOOKUP($A12,'SurveyRpt_20150223 (1)'!$A$34:$AN$735,32,FALSE) -> Yes | U12: =VLOOKUP($A12,'SurveyRpt_20150223 (1)'!$A$34:$AN$735,34,FALSE) -> Yes | V12: =VLOOKUP($A12,'SurveyRpt_20150223 (1)'!$A$34:$AN$735,36,FALSE) -> Yes | W12: =VLOOKUP($A12,'SurveyRpt_20150223 (1)'!$A$34:$AN$735,38,FALSE) -> No
A13: KSIDDIQUI5@csc.com | B13: =TRIM(LEFT(A13,FIND("@",A13)-1)) -> KSIDDIQUI5 | C13: =VLOOKUP(B13,'Compiled Agents'!A:H,2,FALSE) -> Platform | D13: =VLOOKUP(B13,'Compiled Agents'!A:H,4,FALSE) -> Noida | E13: =VLOOKUP(B13,'Compiled Agents'!A:H,5,FALSE) -> Wave2 | F13: =VLOOKUP(B13,'Compiled Agents'!A:H,6,FALSE) -> Yellow | G13: =VLOOKUP($A13,'SurveyRpt_20150223 (1)'!$A$34:$AN$735,6,FALSE) -> 15 | H13: =VLOOKUP($A13,'SurveyRpt_20150223 (1)'!$A$34:$AN$735,8,FALSE) -> Yes | I13: =VLOOKUP($A13,'SurveyRpt_20150223 (1)'!$A$34:$AN$735,10,FALSE) -> Yes | J13: =VLOOKUP($A13,'SurveyRpt_20150223 (1)'!$A$34:$AN$735,12,FALSE) -> Yes | K13: =VLOOKUP($A13,'SurveyRpt_20150223 (1)'!$A$34:$AN$735,14,FALSE) -> No | L13: =VLOOKUP($A13,'SurveyRpt_20150223 (1)'!$A$34:$AN$735,16,FALSE) -> Yes | M13: =VLOOKUP($A13,'SurveyRpt_20150223 (1)'!$A$34:$AN$735,18,FALSE) -> Yes | N13: =VLOOKUP($A13,'SurveyRpt_20150223 (1)'!$A$34:$AN$735,20,FALSE) -> Yes | O13: =VLOOKUP($A13,'SurveyRpt_20150223 (1)'!$A$34:$AN$735,22,FALSE) -> Yes | P13: =VLOOKUP($A13,'SurveyRpt_20150223 (1)'!$A$34:$AN$735,24,FALSE) -> Yes | Q13: =VLOOKUP($A13,'SurveyRpt_20150223 (1)'!$A$34:$AN$735,26,FALSE) -> Yes | R13: =VLOOKUP($A13,'SurveyRpt_20150223 (1)'!$A$34:$AN$735,28,FALSE) -> Yes | S13: =VLOOKUP($A13,'SurveyRpt_20150223 (1)'!$A$34:$AN$735,30,FALSE) -> Yes | T13: =VLOOKUP($A13,'SurveyRpt_20150223 (1)'!$A$34:$AN$735,32,FALSE) -> Yes | U13: =VLOOKUP($A13,'SurveyRpt_20150223 (1)'!$A$34:$AN$735,34,FALSE) -> Yes | V13: =VLOOKUP($A13,'SurveyRpt_20150223 (1)'!$A$34:$AN$735,36,FALSE) -> Yes | W13: =VLOOKUP($A13,'SurveyRpt_20150223 (1)'!$A$34:$AN$735,38,FALSE) -> Yes
... A702: VBHARDWAJ3@csc.com | B702: =TRIM(LEFT(A702,FIND("@",A702)-1)) -> VBHARDWAJ3 | C702: =VLOOKUP(B702,'Compiled Agents'!A:H,2,FALSE) -> Platform | D702: =VLOOKUP(B702,'Compiled Agents'!A:H,4,FALSE) -> Noida | E702: =VLOOKUP(B702,'Compiled Agents'!A:H,5,FALSE) -> Wave2 | F702: =VLOOKUP(B702,'Compiled Agents'!A:H,6,FALSE) -> Purple | G702: =VLOOKUP($A702,'SurveyRpt_20150223 (1)'!$A$34:$AN$735,6,FALSE) -> 16 | H702: =VLOOKUP($A702,'SurveyRpt_20150223 (1)'!$A$34:$AN$735,8,FALSE) -> Yes | I702: =VLOOKUP($A702,'SurveyRpt_20150223 (1)'!$A$34:$AN$735,10,FALSE) -> Yes | J702: =VLOOKUP($A702,'SurveyRpt_20150223 (1)'!$A$34:$AN$735,12,FALSE) -> Yes | K702: =VLOOKUP($A702,'SurveyRpt_20150223 (1)'!$A$34:$AN$735,14,FALSE) -> Yes | L702: =VLOOKUP($A702,'SurveyRpt_20150223 (1)'!$A$34:$AN$735,16,FALSE) -> Yes | M702: =VLOOKUP($A702,'SurveyRpt_20150223 (1)'!$A$34:$AN$735,18,FALSE) -> Yes | N702: =VLOOKUP($A702,'SurveyRpt_20150223 (1)'!$A$34:$AN$735,20,FALSE) -> Yes | O702: =VLOOKUP($A702,'SurveyRpt_20150223 (1)'!$A$34:$AN$735,22,FALSE) -> Yes | P702: =VLOOKUP($A702,'SurveyRpt_20150223 (1)'!$A$34:$AN$735,24,FALSE) -> Yes | Q702: =VLOOKUP($A702,'SurveyRpt_20150223 (1)'!$A$34:$AN$735,26,FALSE) -> Yes | R702: =VLOOKUP($A702,'SurveyRpt_20150223 (1)'!$A$34:$AN$735,28,FALSE) -> Yes | S702: =VLOOKUP($A702,'SurveyRpt_20150223 (1)'!$A$34:$AN$735,30,FALSE) -> Yes | T702: =VLOOKUP($A702,'SurveyRpt_20150223 (1)'!$A$34:$AN$735,32,FALSE) -> Yes | U702: =VLOOKUP($A702,'SurveyRpt_20150223 (1)'!$A$34:$AN$735,34,FALSE) -> Yes | V702: =VLOOKUP($A702,'SurveyRpt_20150223 (1)'!$A$34:$AN$735,36,FALSE) -> Yes | W702: =VLOOKUP($A702,'SurveyRpt_20150223 (1)'!$A$34:$AN$735,38,FALSE) -> Yes

Sheet D%$&01_DevSheet
A1: D%$&01_00f208c49f30469ab9275e26d24e7a5e | F1: ='SurveyRpt_20150223 (1)'!A:A*"h_l!%" -> #VALUE! | G1: ='SurveyRpt_20150223 (1)'!B:B*"h_l!&" -> #VALUE! | H1: ='SurveyRpt_20150223 (1)'!C:C*"h_l!'" -> #VALUE! | I1: ='SurveyRpt_20150223 (1)'!D:D*"h_l!(" -> #VALUE! | J1: ='SurveyRpt_20150223 (1)'!E:E*"h_l!)" -> #VALUE! | K1: ='SurveyRpt_20150223 (1)'!F:F*"h_l!." -> #VALUE! | L1: ='SurveyRpt_20150223 (1)'!G:G*"h_l!/" -> #VALUE! | M1: ='SurveyRpt_20150223 (1)'!H:H*"h_l!0" -> #VALUE! | N1: ='SurveyRpt_20150223 (1)'!I:I*"h_l!1" -> #VALUE! | O1: ='SurveyRpt_20150223 (1)'!J:J*"h_l!2" -> #VALUE! | P1: ='SurveyRpt_20150223 (1)'!K:K*"h_l!3" -> #VALUE! | Q1: ='SurveyRpt_20150223 (1)'!L:L*"h_l!4" -> #VALUE! | R1: ='SurveyRpt_20150223 (1)'!M:M*"h_l!5" -> #VALUE! | S1: ='SurveyRpt_20150223 (1)'!N:N*"h_l!6" -> #VALUE! | T1: ='SurveyRpt_20150223 (1)'!O:O*"h_l!7" -> #VALUE! | U1: ='SurveyRpt_20150223 (1)'!P:P*"h_l!8" -> #VALUE! | V1: ='SurveyRpt_20150223 (1)'!Q:Q*"h_l!9" -> #VALUE! | W1: ='SurveyRpt_20150223 (1)'!R:R*"h_l!:" -> #VALUE! | X1: ='SurveyRpt_20150223 (1)'!S:S*"h_l!;" -> #VALUE! | Y1: ='SurveyRpt_20150223 (1)'!T:T*"h_l!<" -> #VALUE! | Z1: ='SurveyRpt_20150223 (1)'!U:U*"h_l!=" -> #VALUE! | AA1: ='SurveyRpt_20150223 (1)'!V:V*"h_l!>" -> #VALUE! | AB1: ='SurveyRpt_20150223 (1)'!W:W*"h_l!?" -> #VALUE! | AC1: ='SurveyRpt_20150223 (1)'!X:X*"h_l!@" -> #VALUE! | AD1: ='SurveyRpt_20150223 (1)'!Y:Y*"h_l!A" -> #VALUE! | AE1: ='SurveyRpt_20150223 (1)'!Z:Z*"h_l!B" -> #VALUE! | AF1: ='SurveyRpt_20150223 (1)'!AA:AA*"h_l!C" -> #VALUE! | AG1: ='SurveyRpt_20150223 (1)'!AB:AB*"h_l!D" -> #VALUE! | AH1: ='SurveyRpt_20150223 (1)'!AC:AC*"h_l!E" -> #VALUE! | AI1: ='SurveyRpt_20150223 (1)'!AD:AD*"h_l!F" -> #VALUE! | AJ1: ='SurveyRpt_20150223 (1)'!AE:AE*"h_l!G" -> #VALUE! | AK1: ='SurveyRpt_20150223 (1)'!AF:AF*"h_l!H" -> #VALUE! | AL1: ='SurveyRpt_20150223 (1)'!AG:AG*"h_l!I" -> #VALUE! | AM1: ='SurveyRpt_20150223 (1)'!AH:AH*"h_l!J" -> #VALUE! | AN1: ='SurveyRpt_20150223 (1)'!AI:AI*"h_l!K" -> #VALUE! | AO1: ='SurveyRpt_20150223 (1)'!AJ:AJ*"h_l!L" -> #VALUE! | AP1: ='SurveyRpt_20150223 (1)'!AK:AK*"h_l!M" -> #VALUE! | AQ1: ='SurveyRpt_20150223 (1)'!AL:AL*"h_l!N" -> #VALUE! | AR1: ='SurveyRpt_20150223 (1)'!AM:AM*"h_l!O" -> #VALUE! | AS1: ='SurveyRpt_20150223 (1)'!AN:AN*"h_l!P" -> #VALUE! | AT1: ='SurveyRpt_20150223 (1)'!AO:AO*"h_l!Q" -> #VALUE! | AU1: ='SurveyRpt_20150223 (1)'!AP:AP*"h_l!R" -> #VALUE! | AV1: ='SurveyRpt_20150223 (1)'!AQ:AQ*"h_l!S" -> #VALUE! | AW1: ='SurveyRpt_20150223 (1)'!AR:AR*"h_l!T" -> #VALUE! | AX1: ='SurveyRpt_20150223 (1)'!AS:AS*"h_l!U" -> #VALUE! | AY1: ='SurveyRpt_20150223 (1)'!AT:AT*"h_l!V" -> #VALUE! | AZ1: ='SurveyRpt_20150223 (1)'!AU:AU*"h_l!W" -> #VALUE! | BA1: ='SurveyRpt_20150223 (1)'!AV:AV*"h_l!X" -> #VALUE! | BB1: ='SurveyRpt_20150223 (1)'!AW:AW*"h_l!Y" -> #VALUE! | BC1: ='SurveyRpt_20150223 (1)'!AX:AX*"h_l!Z" -> #VALUE! | BD1: ='SurveyRpt_20150223 (1)'!AY:AY*"h_l![" -> #VALUE! | BE1: ='SurveyRpt_20150223 (1)'!AZ:AZ*"h_l!\" -> #VALUE! | BF1: ='SurveyRpt_20150223 (1)'!BA:BA*"h_l!]" -> #VALUE! | BG1: ='SurveyRpt_20150223 (1)'!BB:BB*"h_l!^" -> #VALUE! | BH1: ='SurveyRpt_20150223 (1)'!BC:BC*"h_l!_" -> #VALUE! | BI1: ='SurveyRpt_20150223 (1)'!BD:BD*"h_l!`" -> #VALUE! | BJ1: ='SurveyRpt_20150223 (1)'!BE:BE*"h_l!a" -> #VALUE! | BK1: ='SurveyRpt_20150223 (1)'!BF:BF*"h_l!b" -> #VALUE! | BL1: ='SurveyRpt_20150223 (1)'!BG:BG*"h_l!c" -> #VALUE! | BM1: ='SurveyRpt_20150223 (1)'!BH:BH*"h_l!d" -> #VALUE! | BN1: ='SurveyRpt_20150223 (1)'!BI:BI*"h_l!e" -> #VALUE! | BO1: ='SurveyRpt_20150223 (1)'!BJ:BJ*"h_l!f" -> #VALUE! | BP1: ='SurveyRpt_20150223 (1)'!BK:BK*"h_l!g" -> #VALUE! | BQ1: ='SurveyRpt_20150223 (1)'!BL:BL*"h_l!h" -> #VALUE! | BR1: ='SurveyRpt_20150223 (1)'!BM:BM*"h_l!i" -> #VALUE! | BS1: ='SurveyRpt_20150223 (1)'!BN:BN*"h_l!j" -> #VALUE! | BT1: ='SurveyRpt_20150223 (1)'!BO:BO*"h_l!k" -> #VALUE! | BU1: ='SurveyRpt_20150223 (1)'!BP:BP*"h_l!l" -> #VALUE! | BV1: ='SurveyRpt_20150223 (1)'!BQ:BQ*"h_l!m" -> #VALUE! | BW1: ='SurveyRpt_20150223 (1)'!BR:BR*"h_l!n" -> #VALUE! | BX1: ='SurveyRpt_20150223 (1)'!BS:BS*"h_l!o" -> #VALUE! | BY1: ='SurveyRpt_20150223 (1)'!BT:BT*"h_l!p" -> #VALUE! | BZ1: ='SurveyRpt_20150223 (1)'!BU:BU*"h_l!q" -> #VALUE! | CA1: ='SurveyRpt_20150223 (1)'!BV:BV*"h_l!r" -> #VALUE! | CB1: ='SurveyRpt_20150223 (1)'!BW:BW*"h_l!s" -> #VALUE! | CC1: ='SurveyRpt_20150223 (1)'!BX:BX*"h_l!t" -> #VALUE! | CD1: ='SurveyRpt_20150223 (1)'!BY:BY*"h_l!u" -> #VALUE! | CE1: ='SurveyRpt_20150223 (1)'!BZ:BZ*"h_l!v" -> #VALUE! | CF1: ='SurveyRpt_20150223 (1)'!CA:CA*"h_l!w" -> #VALUE! | CG1: ='SurveyRpt_20150223 (1)'!CB:CB*"h_l!x" -> #VALUE! | CH1: ='SurveyRpt_20150223 (1)'!CC:CC*"h_l!y" -> #VALUE! | CI1: ='SurveyRpt_20150223 (1)'!CD:CD*"h_l!z" -> #VALUE! | CJ1: ='SurveyRpt_20150223 (1)'!CE:CE*"h_l!{" -> #VALUE! | CK1: ='SurveyRpt_20150223 (1)'!CF:CF*"h_l!|" -> #VALUE! | CL1: ='SurveyRpt_20150223 (1)'!CG:CG*"h_l!}" -> #VALUE! | CM1: ='SurveyRpt_20150223 (1)'!CH:CH*"h_l!~" -> #VALUE! | CN1: ='SurveyRpt_20150223 (1)'!CI:CI*"h_l!$#" -> #VALUE! | CO1: ='SurveyRpt_20150223 (1)'!CJ:CJ*"h_l!$$" -> #VALUE! | CP1: ='SurveyRpt_20150223 (1)'!CK:CK*"h_l!$%" -> #VALUE! | CQ1: ='SurveyRpt_20150223 (1)'!CL:CL*"h_l!$&" -> #VALUE! | CR1: ='SurveyRpt_20150223 (1)'!1:1-"h_l!$'" -> #VALUE! | CS1: ='SurveyRpt_20150223 (1)'!2:2-"h_l!$(" -> #VALUE! | CT1: ='SurveyRpt_20150223 (1)'!3:3-"h_l!$)" -> #VALUE! | CU1: ='SurveyRpt_20150223 (1)'!4:4-"h_l!$." -> #VALUE! | CV1: ='SurveyRpt_20150223 (1)'!5:5-"h_l!$/" -> #VALUE! | CW1: ='SurveyRpt_20150223 (1)'!6:6-"h_l!$0" -> #VALUE! | CX1: ='SurveyRpt_20150223 (1)'!7:7-"h_l!$1" -> #VALUE! | CY1: ='SurveyRpt_20150223 (1)'!8:8-"h_l!$2" -> #VALUE! | CZ1: ='SurveyRpt_20150223 (1)'!9:9-"h_l!$3" -> #VALUE! | DA1: ='SurveyRpt_20150223 (1)'!10:10-"h_l!$4" -> #VALUE! | DB1: ='SurveyRpt_20150223 (1)'!11:11-"h_l!$5" -> #VALUE! | DC1: ='SurveyRpt_20150223 (1)'!12:12-"h_l!$6" -> #VALUE! | DD1: ='SurveyRpt_20150223 (1)'!13:13-"h_l!$7" -> #VALUE! | DE1: ='SurveyRpt_20150223 (1)'!14:14-"h_l!$8" -> #VALUE! | DF1: ='SurveyRpt_20150223 (1)'!15:15-"h_l!$9" -> #VALUE! | DG1: ='SurveyRpt_20150223 (1)'!16:16-"h_l!$:" -> #VALUE! | DH1: ='SurveyRpt_20150223 (1)'!17:17-"h_l!$;" -> #VALUE! | DI1: ='SurveyRpt_20150223 (1)'!18:18-"h_l!$<" -> #VALUE! | DJ1: ='SurveyRpt_20150223 (1)'!19:19-"h_l!$=" -> #VALUE! | DK1: ='SurveyRpt_20150223 (1)'!20:20-"h_l!$>" -> #VALUE! | DL1: ='SurveyRpt_20150223 (1)'!21:21-"h_l!$?" -> #VALUE! | DM1: ='SurveyRpt_20150223 (1)'!22:22-"h_l!$@" -> #VALUE! | DN1: ='SurveyRpt_20150223 (1)'!23:23-"h_l!$A" -> #VALUE! | DO1: ='SurveyRpt_20150223 (1)'!24:24-"h_l!$B" -> #VALUE! | DP1: ='SurveyRpt_20150223 (1)'!25:25-"h_l!$C" -> #VALUE! | DQ1: ='SurveyRpt_20150223 (1)'!26:26-"h_l!$D" -> #VALUE! | DR1: ='SurveyRpt_20150223 (1)'!27:27-"h_l!$E" -> #VALUE! | DS1: ='SurveyRpt_20150223 (1)'!28:28-"h_l!$F" -> #VALUE! | DT1: ='SurveyRpt_20150223 (1)'!29:29-"h_l!$G" -> #VALUE! | DU1: ='SurveyRpt_20150223 (1)'!30:30-"h_l!$H" -> #VALUE! | DV1: ='SurveyRpt_20150223 (1)'!31:31-"h_l!$I" -> #VALUE! | DW1: ='SurveyRpt_20150223 (1)'!32:32-"h_l!$J" -> #VALUE! | DX1: ='SurveyRpt_20150223 (1)'!33:33-"h_l!$K" -> #VALUE! | DY1: ='SurveyRpt_20150223 (1)'!34:34-"h_l!$L" -> #VALUE! | DZ1: ='SurveyRpt_20150223 (1)'!35:35-"h_l!$M" -> #VALUE! | EA1: ='SurveyRpt_20150223 (1)'!36:36-"h_l!$N" -> #VALUE! | EB1: ='SurveyRpt_20150223 (1)'!37:37-"h_l!$O" -> #VALUE! | EC1: ='SurveyRpt_20150223 (1)'!38:38-"h_l!$P" -> #VALUE! | ED1: ='SurveyRpt_20150223 (1)'!39:39-"h_l!$Q" -> #VALUE! | EE1: ='SurveyRpt_20150223 (1)'!40:40-"h_l!$R" -> #VALUE! | EF1: ='SurveyRpt_20150223 (1)'!41:41-"h_l!$S" -> #VALUE! | EG1: ='SurveyRpt_20150223 (1)'!42:42-"h_l!$T" -> #VALUE! | EH1: ='SurveyRpt_20150223 (1)'!43:43-"h_l!$U" -> #VALUE! | EI1: ='SurveyRpt_20150223 (1)'!44:44-"h_l!$V" -> #VALUE! | EJ1: ='SurveyRpt_20150223 (1)'!45:45-"h_l!$W" -> #VALUE! | EK1: ='SurveyRpt_20150223 (1)'!46:46-"h_l!$X" -> #VALUE! | EL1: ='SurveyRpt_20150223 (1)'!47:47-"h_l!$Y" -> #VALUE! | EM1: ='SurveyRpt_20150223 (1)'!48:48-"h_l!$Z" -> #VALUE! | EN1: ='SurveyRpt_20150223 (1)'!49:49-"h_l!$[" -> #VALUE! | EO1: ='SurveyRpt_20150223 (1)'!50:50-"h_l!$\" -> #VALUE! | EP1: ='SurveyRpt_20150223 (1)'!51:51-"h_l!$]" -> #VALUE! | EQ1: ='SurveyRpt_20150223 (1)'!52:52-"h_l!$^" -> #VALUE! | ER1: ='SurveyRpt_20150223 (1)'!53:53-"h_l!$_" -> #VALUE! | ES1: ='SurveyRpt_20150223 (1)'!54:54-"h_l!$`" -> #VALUE! | ET1: ='SurveyRpt_20150223 (1)'!55:55-"h_l!$a" -> #VALUE! | EU1: ='SurveyRpt_20150223 (1)'!56:56-"h_l!$b" -> #VALUE! | EV1: ='SurveyRpt_20150223 (1)'!57:57-"h_l!$c" -> #VALUE! | EW1: ='SurveyRpt_20150223 (1)'!58:58-"h_l!$d" -> #VALUE! | EX1: ='SurveyRpt_20150223 (1)'!59:59-"h_l!$e" -> #VALUE! | EY1: ='SurveyRpt_20150223 (1)'!60:60-"h_l!$f" -> #VALUE! | EZ1: ='SurveyRpt_20150223 (1)'!61:61-"h_l!$g" -> #VALUE! | FA1: ='SurveyRpt_20150223 (1)'!62:62-"h_l!$h" -> #VALUE! | FB1: ='SurveyRpt_20150223 (1)'!63:63-"h_l!$i" -> #VALUE! | FC1: ='SurveyRpt_20150223 (1)'!64:64-"h_l!$j" -> #VALUE! | FD1: ='SurveyRpt_20150223 (1)'!65:65-"h_l!$k" -> #VALUE! | FE1: ='SurveyRpt_20150223 (1)'!66:66-"h_l!$l" -> #VALUE! | FF1: ='SurveyRpt_20150223 (1)'!67:67-"h_l!$m" -> #VALUE! | FG1: ='SurveyRpt_20150223 (1)'!68:68-"h_l!$n" -> #VALUE! | FH1: ='SurveyRpt_20150223 (1)'!69:69-"h_l!$o" -> #VALUE! | FI1: ='SurveyRpt_20150223 (1)'!70:70-"h_l!$p" -> #VALUE! | FJ1: ='SurveyRpt_20150223 (1)'!71:71-"h_l!$q" -> #VALUE! | FK1: ='SurveyRpt_20150223 (1)'!72:72-"h_l!$r" -> #VALUE! | FL1: ='SurveyRpt_20150223 (1)'!73:73-"h_l!$s" -> #VALUE! | FM1: ='SurveyRpt_20150223 (1)'!74:74-"h_l!$t" -> #VALUE! | FN1: ='SurveyRpt_20150223 (1)'!75:75-"h_l!$u" -> #VALUE! | FO1: ='SurveyRpt_20150223 (1)'!76:76-"h_l!$v" -> #VALUE! | FP1: ='SurveyRpt_20150223 (1)'!77:77-"h_l!$w" -> #VALUE! | FQ1: ='SurveyRpt_20150223 (1)'!78:78-"h_l!$x" -> #VALUE! | FR1: ='SurveyRpt_20150223 (1)'!79:79-"h_l!$y" -> #VALUE! | FS1: ='SurveyRpt_20150223 (1)'!80:80-"h_l!$z" -> #VALUE! | FT1: ='SurveyRpt_20150223 (1)'!81:81-"h_l!${" -> #VALUE! | FU1: ='SurveyRpt_20150223 (1)'!82:82-"h_l!$|" -> #VALUE! | FV1: ='SurveyRpt_20150223 (1)'!83:83-"h_l!$}" -> #VALUE! | FW1: ='SurveyRpt_20150223 (1)'!84:84-"h_l!$~" -> #VALUE! | FX1: ='SurveyRpt_20150223 (1)'!85:85-"h_l!%#" -> #VALUE! | FY1: ='SurveyRpt_20150223 (1)'!86:86-"h_l!%$" -> #VALUE! | FZ1: ='SurveyRpt_20150223 (1)'!87:87-"h_l!%%" -> #VALUE! | GA1: ='SurveyRpt_20150223 (1)'!88:88-"h_l!%&" -> #VALUE! | GB1: ='SurveyRpt_20150223 (1)'!89:89-"h_l!%'" -> #VALUE! | GC1: ='SurveyRpt_20150223 (1)'!90:90-"h_l!%(" -> #VALUE! | GD1: ='SurveyRpt_20150223 (1)'!91:91-"h_l!%)" -> #VALUE! | GE1: ='SurveyRpt_20150223 (1)'!92:92-"h_l!%." -> #VALUE! | GF1: ='SurveyRpt_20150223 (1)'!93:93-"h_l!%/" -> #VALUE! | GG1: ='SurveyRpt_20150223 (1)'!94:94-"h_l!%0" -> #VALUE! | GH1: ='SurveyRpt_20150223 (1)'!95:95-"h_l!%1" -> #VALUE! | GI1: ='SurveyRpt_20150223 (1)'!96:96-"h_l!%2" -> #VALUE! | GJ1: ='SurveyRpt_20150223 (1)'!97:97-"h_l!%3" -> #VALUE! | GK1: ='SurveyRpt_20150223 (1)'!98:98-"h_l!%4" -> #VALUE! | GL1: ='SurveyRpt_20150223 (1)'!99:99-"h_l!%5" -> #VALUE! | GM1: ='SurveyRpt_20150223 (1)'!100:100-"h_l!%6" -> #VALUE! | GN1: ='SurveyRpt_20150223 (1)'!101:101-"h_l!%7" -> #VALUE! | GO1: ='SurveyRpt_20150223 (1)'!102:102-"h_l!%8" -> #VALUE! | GP1: ='SurveyRpt_20150223 (1)'!103:103-"h_l!%9" -> #VALUE! | GQ1: ='SurveyRpt_20150223 (1)'!104:104-"h_l!%:" -> #VALUE! | GR1: ='SurveyRpt_20150223 (1)'!105:105-"h_l!%;" -> #VALUE! | GS1: ='SurveyRpt_20150223 (1)'!106:106-"h_l!%<" -> #VALUE! | GT1: ='SurveyRpt_20150223 (1)'!107:107-"h_l!%=" -> #VALUE! | GU1: ='SurveyRpt_20150223 (1)'!108:108-"h_l!%>" -> #VALUE! | GV1: ='SurveyRpt_20150223 (1)'!109:109-"h_l!%?" -> #VALUE! | GW1: ='SurveyRpt_20150223 (1)'!110:110-"h_l!%@" -> #VALUE! | GX1: ='SurveyRpt_20150223 (1)'!111:111-"h_l!%A" -> #VALUE! | GY1: ='SurveyRpt_20150223 (1)'!112:112-"h_l!%B" -> #VALUE! | GZ1: ='SurveyRpt_20150223 (1)'!113:113-"h_l!%C" -> #VALUE! | HA1: ='SurveyRpt_20150223 (1)'!114:114-"h_l!%D" -> #VALUE! | HB1: ='SurveyRpt_20150223 (1)'!115:115-"h_l!%E" -> #VALUE! | HC1: ='SurveyRpt_20150223 (1)'!116:116-"h_l!%F" -> #VALUE! | HD1: ='SurveyRpt_20150223 (1)'!117:117-"h_l!%G" -> #VALUE! | HE1: ='SurveyRpt_20150223 (1)'!118:118-"h_l!%H" -> #VALUE! | HF1: ='SurveyRpt_20150223 (1)'!119:119-"h_l!%I" -> #VALUE! | HG1: ='SurveyRpt_20150223 (1)'!120:120-"h_l!%J" -> #VALUE! | HH1: ='SurveyRpt_20150223 (1)'!121:121-"h_l!%K" -> #VALUE! | HI1: ='SurveyRpt_20150223 (1)'!122:122-"h_l!%L" -> #VALUE! | HJ1: ='SurveyRpt_20150223 (1)'!123:123-"h_l!%M" -> #VALUE! | HK1: ='SurveyRpt_20150223 (1)'!124:124-"h_l!%N" -> #VALUE! | HL1: ='SurveyRpt_20150223 (1)'!125:125-"h_l!%O" -> #VALUE! | HM1: ='SurveyRpt_20150223 (1)'!126:126-"h_l!%P" -> #VALUE! | HN1: ='SurveyRpt_20150223 (1)'!127:127-"h_l!%Q" -> #VALUE! | HO1: ='SurveyRpt_20150223 (1)'!128:128-"h_l!%R" -> #VALUE! | HP1: ='SurveyRpt_20150223 (1)'!129:129-"h_l!%S" -> #VALUE! | HQ1: ='SurveyRpt_20150223 (1)'!130:130-"h_l!%T" -> #VALUE! | HR1: ='SurveyRpt_20150223 (1)'!131:131-"h_l!%U" -> #VALUE! | HS1: ='SurveyRpt_20150223 (1)'!132:132-"h_l!%V" -> #VALUE! | HT1: ='SurveyRpt_20150223 (1)'!133:133-"h_l!%W" -> #VALUE! | HU1: ='SurveyRpt_20150223 (1)'!134:134-"h_l!%X" -> #VALUE! | HV1: ='SurveyRpt_20150223 (1)'!135:135-"h_l!%Y" -> #VALUE! | HW1: ='SurveyRpt_20150223 (1)'!136:136-"h_l!%Z" -> #VALUE! | HX1: ='SurveyRpt_20150223 (1)'!137:137-"h_l!%[" -> #VALUE! | HY1: ='SurveyRpt_20150223 (1)'!138:138-"h_l!%\" -> #VALUE! | HZ1: ='SurveyRpt_20150223 (1)'!139:139-"h_l!%]" -> #VALUE! | IA1: ='SurveyRpt_20150223 (1)'!140:140-"h_l!%^" -> #VALUE! | IB1: ='SurveyRpt_20150223 (1)'!141:141-"h_l!%_" -> #VALUE! | IC1: ='SurveyRpt_20150223 (1)'!142:142-"h_l!%`" -> #VALUE! | ID1: ='SurveyRpt_20150223 (1)'!143:143-"h_l!%a" -> #VALUE! | IE1: ='SurveyRpt_20150223 (1)'!144:144-"h_l!%b" -> #VALUE! | IF1: ='SurveyRpt_20150223 (1)'!145:145-"h_l!%c" -> #VALUE! | IG1: ='SurveyRpt_20150223 (1)'!146:146-"h_l!%d" -> #VALUE! | IH1: ='SurveyRpt_20150223 (1)'!147:147-"h_l!%e" -> #VALUE! | II1: ='SurveyRpt_20150223 (1)'!148:148-"h_l!%f" -> #VALUE! | IJ1: ='SurveyRpt_20150223 (1)'!149:149-"h_l!%g" -> #VALUE! | IK1: ='SurveyRpt_20150223 (1)'!150:150-"h_l!%h" -> #VALUE! | IL1: ='SurveyRpt_20150223 (1)'!151:151-"h_l!%i" -> #VALUE! | IM1: ='SurveyRpt_20150223 (1)'!152:152-"h_l!%j" -> #VALUE! | IN1: ='SurveyRpt_20150223 (1)'!153:153-"h_l!%k" -> #VALUE! | IO1: ='SurveyRpt_20150223 (1)'!154:154-"h_l!%l" -> #VALUE! | IP1: ='SurveyRpt_20150223 (1)'!155:155-"h_l!%m" -> #VALUE! | IQ1: ='SurveyRpt_20150223 (1)'!156:156-"h_l!%n" -> #VALUE! | IR1: ='SurveyRpt_20150223 (1)'!157:157-"h_l!%o" -> #VALUE! | IS1: ='SurveyRpt_20150223 (1)'!158:158-"h_l!%p" -> #VALUE! | IT1: ='SurveyRpt_20150223 (1)'!159:159-"h_l!%q" -> #VALUE! | IU1: ='SurveyRpt_20150223 (1)'!160:160-"h_l!%r" -> #VALUE! | IV1: ='SurveyRpt_20150223 (1)'!161:161-"h_l!%s" -> #VALUE!
